Workbook

Sheet Articles
A1: No | B1: Date | C1: Year | D1: Title | E1: Keyword group (Tamil) | F1: Keyword group (English) | G1: Matched terms | H1: Places mentioned | I1: Source | J1: Source country | K1: Language | L1: URL | M1: Archive copy | N1: Snippet | O1: Match basis | P1: Found via | Q1: Found on
A2: 1 | B2: 2026-10-29 | C2: 2026 | D2: பாண்டியர் கால கல்வெட்டு புதுக்கோட்டையில் கண்டெடுப்பு | E2: கல்வெட்டு | F2: Inscription / Epigraphy | G2: கல்வெட்டு | I2: dinamalar.com | J2: India | K2: Tamil | L2: https://www.dinamalar.com/templenews/165979 | N2: பாண்டியர் கால கல்வெட்டு புதுக்கோட்டையில் கண்டெடுப்பு புதுக்கோட்டை: புதுக்கோட்டை மாவட்டம், பொதுஒக்கூர் என்ற ஊரில், வரலாற்று ஆய்வாளர் காளிதாஸ் குழுவினர், கள ஆய்வு மேற்கொண்டனர். அப்போது, பிள்ளையார் கோவில் திடலுக்கு அருகே கல்வெட்டு ஒன்று, மண்ணில் புதையுண்டு கிடப்பதை கண்டெடுத்தனர். இது குறித்து, காளிதாஸ்… | O2: full-text | P2: gnews | Q2: 2026-10-30
A3: 2 | B3: 2026-10-28 | C3: 2026 | D3: கீழடி அருங்காட்சியகத்தில் ஆய்வு | E3: தொல்லியல் | F3: Archaeology / Excavation | G3: தொல்லியல், தொல்லியல் துறை, அகழாய்வு, கீழடி | I3: dinamalar.com | J3: India | K3: Tamil | L3: https://www.dinamalar.com/news/tamil-nadu-district-news-sivagangai/exploration-at-the-keezhadi-museum/4361468 | N3: உள்ளடக்கத்திற்கு செல்ல ADDED : அக் 28, 2026 07:11 PM அ நிறம் | அளவு கீழடி: தமிழக தொல்லியல் துறை கமிஷனராக சங்கர் செப்டம்பரில் நியமிக்கப்பட்டார். இதனையடுத்து கீழடி தொல் பொருள் மற்றும் திறந்த வெளி அருங்காட்சியகம், 11ம் கட்ட அகழாய்வு நடைபெறும் இடங்கள் ஆகியவற்றை ஆய்வு செய்தார். அருங்காட்சியகத்தில் கூடுதல… | O3: full-text | P3: gnews | Q3: 2026-10-29
A4: 3 | B4: 2026-10-28 | C4: 2026 | D4: பாண்டியர் கால கல்வெட்டு புதுக்கோட்டையில் கண்டெடுப்பு | E4: கல்வெட்டு | F4: Inscription / Epigraphy | G4: கல்வெட்டு | I4: dinamalar.com | J4: India | K4: Tamil | L4: https://www.dinamalar.com/news/tamil-nadu-district-news-pudukottai/pandyan-period-inscription-discovered-in-pudukkottai/4360672 | N4: உள்ளடக்கத்திற்கு செல்ல பாண்டியர் கால கல்வெட்டு புதுக்கோட்டையில் கண்டெடுப்பு UPDATED : அக் 27, 2026 07:10 PM ADDED : அக் 27, 2026 07:00 PM புதுக்கோட்டை: புதுக்கோட்டை மாவட்டம், பொதுஒக்கூர் என்ற ஊரில், வரலாற்று ஆய்வாளர் காளிதாஸ் குழுவினர், கள ஆய்வு மேற்கொண்டனர். அப்போது, பிள்ளையார் கோவில் திடலுக்கு அரு… | O4: full-text | P4: gnews | Q4: 2026-10-28
A5: 4 | B5: 2026-10-28 | C5: 2026 | D5: பாண்டியர் கால கல்வெட்டு புதுக்கோட்டையில் கண்டெடுப்பு | E5: கல்வெட்டு | F5: Inscription / Epigraphy | G5: கல்வெட்டு | H5: Kerala | I5: temple.dinamalar.com | J5: India | K5: Tamil | L5: https://temple.dinamalar.com/news_detail.php?id=165979 | N5: | | | | முதல் பக்கம் » இன்றைய செய்திகள் | | | பாண்டியர் கால கல்வெட்டு புதுக்கோட்டையில் கண்டெடுப்பு பதிவு செய்த நாள் 28 அக் 2026 11:10 புதுக்கோட்டை: புதுக்கோட்டை மாவட்டம், பொதுஒக்கூர் என்ற ஊரில், வரலாற்று ஆய்வாளர் காளிதாஸ் குழுவினர், கள ஆய்வு மேற்கொண்டனர். அப்போது, பிள்ளையார் கோவில் திடலுக்கு அருகே க… | O5: full-text | P5: gnews | Q5: 2026-10-29
A6: 5 | B6: 2026-10-27 | C6: 2026 | D6: 10ம் நுாற்றாண்டு கல்வெட்டு அகத்தீஸ்வரர் கோவிலில் கண்டுபிடிப்பு | E6: கல்வெட்டு, தொல்லியல் | F6: Inscription / Epigraphy, Archaeology / Excavation | G6: கல்வெட்டு, கல்வெட்டுகள், தொல்லியல் | I6: dinamalar.com | J6: India | K6: Tamil | L6: https://www.dinamalar.com/news/tamil-nadu-district-news-kancheepuram/10th-century-inscription-discovered-in-agadheshwara-temple/4359447 | N6: உள்ளடக்கத்திற்கு செல்ல 10ம் நுாற்றாண்டு கல்வெட்டு அகத்தீஸ்வரர் கோவிலில் கண்டுபிடிப்பு ADDED : அக் 26, 2026 04:26 PM வாலாஜாபாத்: வல்லப்பாக்கம் அகத்தீஸ்வரர் கோவிலில், 10ம் நுாற்றாண்டைச் சேர்ந்த கல்வெட்டு நேற்று (அக்.,25) கண்டுபிடிக்கபட்டு உள்ளது. இதுகுறித்து, வாலாஜாபாத் வட்டார வரலாற்று ஆய்வு மைய தலைவர… | O6: full-text | P6: gnews | Q6: 2026-10-27
A7: 6 | B7: 2026-10-27 | C7: 2026 | D7: தமிழ் ஆசிரியர்கள் பறக்கலாம்!: நம்பிக்கை அளிக்கிறார் பேரூர் ஆதினம் | E7: கல்வெட்டு, தொல்லியல் | F7: Inscription / Epigraphy, Archaeology / Excavation | G7: கல்வெட்டு, தொல்பொருள் | H7: Sri Lanka, Malaysia | I7: dinamalar.com | J7: India | K7: Tamil | L7: https://www.dinamalar.com/news_detail.asp?id=2268888 | N7: உள்ளடக்கத்திற்கு செல்ல தமிழ் ஆசிரியர்கள் 'பறக்கலாம்!': நம்பிக்கை அளிக்கிறார் பேரூர் ஆதினம் UPDATED : மே 04, 2019 02:00 AM ADDED : மே 04, 2019 01:13 AM 'தமிழ் படிச்சு என்னங்க ஆகப்போகுது...பேசாம பி.காம் சேர்த்து விட்டுருங்க...பேங்குலயாவது வேலை கிடைக்கும்'- இப்படி பெற்றோர்களை தவறாக வழிநடத்தும் கல்வியாள… | O7: full-text | P7: gdelt | Q7: 2026-10-27
A8: 7 | B8: 2026-10-26 | C8: 2026 | D8: 13th Century Hero Stone Helps Understand Medieval History | E8: கல்வெட்டு, நடுகல், தொல்லியல் | F8: Inscription / Epigraphy, Hero stone / Memorial stone, Archaeology / Excavation | G8: inscription, inscriptions, inscribed, hero stone, hero stones, hero-stone, archaeological | H8: Tamil Nadu | I8: deccanchronicle.com | J8: India | K8: English/Other | L8: https://www.deccanchronicle.com/amp/southern-states/tamil-nadu/13th-century-hero-stone-helps-understand-medieval-history-1998923 | N8: 13th Century Hero Stone Helps Understand Medieval History In view of the relative rarity of inscriptions from the period of Vira Vishwanatha in Tamil Nadu, this discovery represents a significant documentary source for further research into the region’s medieval political history COIMBATORE: On the … | O8: full-text | P8: gnews | Q8: 2026-10-27
A9: 8 | B9: 2026-10-26 | C9: 2026 | D9: 13th Century Hero Stone Helps Understand Medieval History | E9: கல்வெட்டு, நடுகல், தொல்லியல் | F9: Inscription / Epigraphy, Hero stone / Memorial stone, Archaeology / Excavation | G9: inscription, inscriptions, inscribed, hero stone, hero stones, hero-stone, archaeological | H9: Tamil Nadu | I9: deccanchronicle.com | J9: India | K9: English/Other | L9: https://www.deccanchronicle.com/southern-states/tamil-nadu/13th-century-hero-stone-helps-understand-medieval-history-1998923 | N9: 13th Century Hero Stone Helps Understand Medieval History In view of the relative rarity of inscriptions from the period of Vira Vishwanatha in Tamil Nadu, this discovery represents a significant documentary source for further research into the region’s medieval political history COIMBATORE: On the … | O9: full-text | P9: gnews | Q9: 2026-10-27
A10: 9 | B10: 2026-10-26 | C10: 2026 | D10: 6th-Century Dharmapuri Hero Stone Sheds Light on Ancient Tamil Nadu | E10: கல்வெட்டு, நடுகல் | F10: Inscription / Epigraphy, Hero stone / Memorial stone | G10: inscriptions, hero stone, hero-stone | H10: Tamil Nadu | I10: deccanchronicle.com | J10: India | K10: English/Other | L10: https://www.deccanchronicle.com/through-the-lens/6th-century-dharmapuri-hero-stone-sheds-light-on-ancient-tamil-nadu-1998926 | N10: 6th-Century Dharmapuri Hero Stone Sheds Light on Ancient Tamil Nadu The newly-documented ‘hero stone inscriptions’ in Dharmapuri belt sheds light on the history of ancient Tamil Nadu as researchers from the Yaakkai Heritage Trust, based in Coimbatore, documented two hero stone inscriptions during fi… | O10: full-text | P10: gnews | Q10: 2026-10-27
A11: 10 | B11: 2026-10-26 | C11: 2026 | D11: Ancient terracotta lamp unearthed in Tamil Nadus Vembakottai | E11: தொல்லியல் | F11: Archaeology / Excavation | G11: archaeology, vembakottai | H11: Tamil Nadu | I11: news.webindia123.com | J11: Unknown | K11: English/Other | L11: https://news.webindia123.com/news/Articles/India/20220504/3937813.html | N11: Monday, October 26, 2026 News | | | Ancient terracotta lamp unearthed in Tamil Nadu's Vembakottai Chennai \| Wednesday, 2022 3:45:09 AM IST | | Excavations at Vembakottai in Virudhunagar district of Tamil Nadu have unearthed an ancient terracotta lamp, which according to archaeologists is an intrins… | O11: full-text | P11: gdelt | Q11: 2026-10-26
A12: 11 | B12: 2026-10-26 | C12: 2026 | D12: Dharmapuri Hero Stones Shed Light on Tamil Nadu’s History | E12: கல்வெட்டு, நடுகல், தொல்லியல் | F12: Inscription / Epigraphy, Hero stone / Memorial stone, Archaeology / Excavation | G12: inscription, inscriptions, epigraphist, vatteluttu, hero stone, hero stones, hero-stone, archaeological | H12: Tamil Nadu | I12: deccanchronicle.com | J12: India | K12: English/Other | L12: https://www.deccanchronicle.com/amp/southern-states/tamil-nadu/dharmapuri-hero-stones-shed-light-on-tamil-nadus-history-1998919 | N12: Dharmapuri Hero Stones Shed Light on Tamil Nadu’s History The newly-documented ‘hero stone inscriptions’ in Dharmapuri belt sheds light on the history of ancient Tamil Nadu as researchers from the Yaakkai Heritage Trust, based in Coimbatore, documented two hero stone inscriptions during field survey… | O12: full-text | P12: gnews | Q12: 2026-10-27
A13: 12 | B13: 2026-10-26 | C13: 2026 | D13: Dharmapuri Hero Stones Shed Light on Tamil Nadu’s History | E13: கல்வெட்டு, நடுகல், தொல்லியல் | F13: Inscription / Epigraphy, Hero stone / Memorial stone, Archaeology / Excavation | G13: inscription, inscriptions, epigraphist, vatteluttu, hero stone, hero stones, hero-stone, archaeological | H13: Tamil Nadu | I13: deccanchronicle.com | J13: India | K13: English/Other | L13: https://www.deccanchronicle.com/southern-states/tamil-nadu/dharmapuri-hero-stones-shed-light-on-tamil-nadus-history-1998919 | N13: Dharmapuri Hero Stones Shed Light on Tamil Nadu’s History The newly-documented ‘hero stone inscriptions’ in Dharmapuri belt sheds light on the history of ancient Tamil Nadu as researchers from the Yaakkai Heritage Trust, based in Coimbatore, documented two hero stone inscriptions during field survey… | O13: full-text | P13: gnews | Q13: 2026-10-27
A14: 13 | B14: 2026-10-26 | C14: 2026 | D14: நாயுடன் போருக்குச் சென்ற வீரன்... செஞ்சி அருகே 500 ஆண்டுகள் பழமையான நடுகல் கண்டுபிடிப்பு | E14: நடுகல் | F14: Hero stone / Memorial stone | G14: நடுகல் | I14: tamil.news18.com | J14: India | K14: Tamil | L14: https://tamil.news18.com/tamil-nadu/16th-century-hero-stone-discovered-near-gingee-in-villupuram-depicting-warrior-with-a-dog-pja-pdp-local18-2239455.html?utm_source=District%20Widget&utm_medium=Desktop&utm_campaign=tamil | N14: நாயுடன் போருக்குச் சென்ற வீரன்... செஞ்சி அருகே 500 ஆண்டுகள் பழமையான நடுகல் கண்டுபிடிப்பு - Reported by:Pooja S - Published by:pradeepa m Last Updated: இந்த நடுகல் கி.பி. 16-ஆம் நூற்றாண்டைச் சேர்ந்ததாகக் கருதப்படுகிறது. பிற்கால விஜயநகரப் பேரரசின் இறுதிக் காலத்துக்கும் தொடக்ககால நாயக்கர் ஆட்சிக் காலத்… | O14: full-text | P14: gnews | Q14: 2026-10-27
A15: 14 | B15: 2026-10-26 | C15: 2026 | D15: நாயுடன் போருக்குச் சென்ற வீரன்... செஞ்சி அருகே 500 ஆண்டுகள் பழமையான நடுகல் கண்டுபிடிப்பு | E15: நடுகல் | F15: Hero stone / Memorial stone | G15: நடுகல் | I15: tamil.news18.com | J15: India | K15: Tamil | L15: https://tamil.news18.com/tamil-nadu/16th-century-hero-stone-discovered-near-gingee-in-villupuram-depicting-warrior-with-a-dog-pja-pdp-local18-2239455.html | N15: நாயுடன் போருக்குச் சென்ற வீரன்... செஞ்சி அருகே 500 ஆண்டுகள் பழமையான நடுகல் கண்டுபிடிப்பு - Reported by:Pooja S - Published by:pradeepa m Last Updated: இந்த நடுகல் கி.பி. 16-ஆம் நூற்றாண்டைச் சேர்ந்ததாகக் கருதப்படுகிறது. பிற்கால விஜயநகரப் பேரரசின் இறுதிக் காலத்துக்கும் தொடக்ககால நாயக்கர் ஆட்சிக் காலத்… | O15: full-text | P15: gnews | Q15: 2026-10-27
A16: 15 | B16: 2026-10-25 | C16: 2026 | D16: ASI refutes Kanimozhi's claim over lack of facilities at Adichanallur heritage site | E16: தொல்லியல் | F16: Archaeology / Excavation | G16: archaeological, adichanallur | H16: Tamil Nadu | I16: aninews.in | J16: India | K16: English/Other | L16: https://www.aninews.in/news/national/general-news/asi-refutes-kanimozhis-claim-over-lack-of-facilities-at-adichanallur-heritage-site20210724135934/ | N16: New Delhi [India], July 24 (ANI): The Archaeological Survey of India (ASI) on Friday refuted DMK MP Kanimozhi's claim that there are no amenities like boundary walls, drinking water, toilets and solar lights around the Adichanallur heritage site in Tamil Nadu. "We Archaeological Survey of India is w… | O16: full-text | P16: gdelt | Q16: 2026-10-25
A17: 16 | B17: 2026-10-25 | C17: 2026 | D17: Assam: Thousands participate in Yoga Utsav in Sivasagar | E17: தொல்லியல் | F17: Archaeology / Excavation | G17: archaeological, adichanallur | H17: Tamil Nadu | I17: news.webindia123.com | J17: Unknown | K17: English/Other | L17: https://news.webindia123.com/news/Articles/India/20220502/3937227.html | N17: Sunday, October 25, 2026 News | | | Assam: Thousands participate in 'Yoga Utsav' in Sivasagar General News \| May 2, 2022 3:53:32 PM IST | | Sivasagar (Assam) [India], May 2: The Ayush Ministry with active support from the Assam government on Monday organised a Yoga Utsav at the iconic holy site of … | O17: full-text | P17: gdelt | Q17: 2026-10-25
A18: 17 | B18: 2026-10-25 | C18: 2026 | D18: Budget 2020: Govt allocates Rs 2,500 cr for development of tourism sector | E18: தொல்லியல் | F18: Archaeology / Excavation | G18: archaeology, archeological, adichanallur | H18: Tamil Nadu | I18: aninews.in | J18: India | K18: English/Other | L18: https://www.aninews.in/news/national/general-news/budget-2020-govt-allocates-rs-2500-cr-for-development-of-tourism-sector20200201205416/ | N18: New Delhi [India], Feb 1 (ANI): To make India an attractive destination for both international and domestic tourists, Finance Minister Nirmala Sitharaman on Saturday proposed to allocate Rs 2,500 crores in the Budget for FY2020-21 for the tourism sector. Besides tourism, Sitharaman also proposed to … | O18: full-text | P18: gdelt | Q18: 2026-10-25
A19: 18 | B19: 2026-10-25 | C19: 2026 | D19: FM Sitharaman proposes Rs 2,500 crore for tourism in 2020-21, eight new museums | E19: தொல்லியல் | F19: Archaeology / Excavation | G19: archeological, adichanallur | H19: Tamil Nadu | I19: aninews.in | J19: India | K19: English/Other | L19: https://www.aninews.in/news/national/general-news/fm-sitharaman-proposes-rs-2500-crore-for-tourism-in-2020-21-eight-new-museums20200201150419/ | N19: New Delhi [India], Feb 1 (ANI): Finance Minister Nirmala Sithraman on Saturday proposed to allocate Rs 2,500 crore in 2020-21 for the tourism sector and construction of eight new museums, which includes building infrastructure around 5 iconic sites. "To make India an attractive destination for both … | O19: full-text | P19: gdelt | Q19: 2026-10-25
A20: 19 | B20: 2026-10-25 | C20: 2026 | D20: Ministry of Ayush to celebrate Yoga Utsav to mark 50 days countdown to International Day of Yoga 2022 | E20: தொல்லியல் | F20: Archaeology / Excavation | G20: archaeological, adichanallur | H20: Tamil Nadu | I20: news.webindia123.com | J20: Unknown | K20: English/Other | L20: https://news.webindia123.com/news/Articles/Business/20220501/3937022.html | N20: Sunday, October 25, 2026 News | | | Ministry of Ayush to celebrate Yoga Utsav to mark 50 days countdown to International Day of Yoga 2022 New Delhi \| May 1, 2022 10:24:01 PM IST | | The Ministry of Ayush in collaboration with state Government of Assam is organizing a grand event at Rang Ghar Ground… | O20: full-text | P20: gdelt | Q20: 2026-10-25
A21: 20 | B21: 2026-10-25 | C21: 2026 | D21: NTK proposes new Tamil Nadu government emblem featuring Thiruvalluvar at election manifesto release program | E21: தொல்லியல் | F21: Archaeology / Excavation | G21: keeladi, adichanallur | H21: Tamil Nadu | I21: aninews.in | J21: India | K21: English/Other | L21: https://aninews.in/news/national/general-news/ntk-proposes-new-tamil-nadu-government-emblem-featuring-thiruvalluvar-at-election-manifesto-release-program20260319132156/ | N21: Chennai (Tamil Nadu) [India], March 19 (ANI): The Naam Tamilar Katchi (NTK) has proposed the new Tamil Nadu government emblem if the party comes to power in the state at the NTK Election Manifesto release program on Thursday in Chennai. According to the party, the redesigned emblem would prominently… | O21: full-text | P21: gdelt | Q21: 2026-10-25
A22: 21 | B22: 2026-10-25 | C22: 2026 | D22: Tamil Nadu floods: 35 deaths reported, focus now on restoring basic services, says chief secretary | E22: தொல்லியல் | F22: Archaeology / Excavation | G22: excavation site, adichanallur | H22: Tamil Nadu | I22: news.webindia123.com | J22: Unknown | K22: English/Other | L22: https://news.webindia123.com/news/Articles/India/20231223/4151975.html | N22: Sunday, October 25, 2026 News | | | Tamil Nadu floods: 35 deaths reported, focus now on restoring basic services, says chief secretary Thoothukudi (Tamil Nadu) \| December 23, 2023 10:21:28 PM IST | | Tamil Nadu Chief Secretary Shiv Das Meena said on Saturday that the rescue operation in the flood-a… | O22: full-text | P22: gdelt | Q22: 2026-10-25
A23: 22 | B23: 2026-10-25 | C23: 2026 | D23: Tamil Nadu: AIADMK, NDA allies hold massive protest against DMK in Dindigul | E23: தொல்லியல் | F23: Archaeology / Excavation | G23: archaeological, keezhadi, adichanallur | H23: Tamil Nadu | I23: aninews.in | J23: India | K23: English/Other | L23: https://aninews.in/news/national/politics/tamil-nadu-aiadmk-nda-allies-hold-massive-protest-against-dmk-in-dindigul20260318041556/ | N23: Dindigul (Tamil Nadu) [India], March 18 (ANI): The All India Anna Dravida Munnetra Kazhagam (AIADMK) and its National Democratic Alliance (NDA) partners staged a joint protest at the Dindigul Clock Tower area to condemn the policies of the state government led by Dravida Munnetra Kazhagam (DMK). AIA… | O23: full-text | P23: gdelt | Q23: 2026-10-25
A24: 23 | B24: 2026-10-25 | C24: 2026 | D24: Tamil Nadu: Political landscape heats up as Opposition protests against DMK ahead of polls | E24: தொல்லியல் | F24: Archaeology / Excavation | G24: archaeological, keezhadi, adichanallur | H24: Tamil Nadu | I24: aninews.in | J24: India | K24: English/Other | L24: https://aninews.in/news/national/politics/tamil-nadu-political-landscape-heats-up-as-opposition-protests-against-dmk-ahead-of-polls20260317180639/ | N24: Tiruppur (Tamil Nadu) [India], March 17 (ANI): The political temperature in Tamil Nadu heightened as opposition parties staged a large-scale protest in Tiruppur, targeting the ruling Dravida Munnetra Kazhagam (DMK) government while also highlighting central government support for local farmers. The … | O24: full-text | P24: gdelt | Q24: 2026-10-25
A25: 24 | B25: 2026-10-25 | C25: 2026 | D25: சிதிலமடைந்த அன்னதான மடத்தில் பழங்கால கல்வெட்டு கண்டெடுப்பு | E25: கல்வெட்டு, தொல்லியல் | F25: Inscription / Epigraphy, Archaeology / Excavation | G25: கல்வெட்டு, தொல்லியல் | I25: dailythanthi.com | J25: India | K25: Tamil | L25: https://www.dailythanthi.com/news/tamilnadu/ancient-inscription-discovered-in-ruined-annadhana-mutt | N25: தமிழக செய்திகள் சிதிலமடைந்த அன்னதான மடத்தில் பழங்கால கல்வெட்டு கண்டெடுப்பு 17 தூண்களுடன் கட்டப்பட்ட இந்த மடத்தில் தனியாக ஒரு விளக்குத்தூணும் உள்ளது. தென்காசி, வாசுதேவநல்லூர் அருகே தொல்லியல் ஆய்வில் சேதமடைந்த மடத்தில் கல்வெட்டு, பழங்கால சிற்பங்கள் கண்டுபிடிக்கப்பட்டுள்ளன. தென்பொதிகை ஆவணக்காப்பகத்தை ச… | O25: full-text | P25: gnews | Q25: 2026-10-26
A26: 25 | B26: 2026-10-25 | C26: 2026 | D26: செஞ்சி அருகே பழைமையான நடுகல் கண்டெடுப்பு | E26: நடுகல் | F26: Hero stone / Memorial stone | G26: நடுகல் | I26: dinamani.com | J26: India | K26: Tamil | L26: https://www.dinamani.com/all-editions/edition-villupuram/villupuram/2026/Oct/25/%E0%AE%9A%E0%AF%86%E0%AE%9E%E0%AF%8D%E0%AE%9A%E0%AE%BF-%E0%AE%85%E0%AE%B0%E0%AF%81%E0%AE%95%E0%AF%87-%E0%AE%AA%E0%AE%B4%E0%AF%88%E0%AE%AE%E0%AF%88%E0%AE%AF%E0%AE%BE%E0%AE%A9-%E0%AE%A8%E0%AE%9F%E0%AF%81%E0%AE%95%E0%AE%B2%E0%AF%8D-%E0%AE%95%E0%AE%A3%E0%AF%8D%E0%AE%9F%E0%AF%86%E0%AE%9F%E0%AF%81%E0%AE%AA%E0%AF%8D%E0%AE%AA%E0%AF%81 | N26: செஞ்சி அருகே பழைமையான நடுகல் கண்டெடுப்பு செஞ்சி அருகே கண்டெடுக்கப்பட்ட கி.பி.16-ஆம் நூற்றாண்டைச் சோ்ந்த நடுகல். விழுப்புரம் மாவட்டம், செஞ்சியை அடுத்துள்ள துத்தபப்பட்டு கிராமத்தில் 16-ஆம் நூற்றாண்டைச் சோ்ந்க நடுகல் கண்டறியப்பட்டது. செஞ்சி அரசு கலை, அறிவியல் கல்லூரி தமிழ்த் துறை பேராசிரியரும், திருவ… | O26: full-text | P26: gnews | Q26: 2026-10-26
A27: 26 | B27: 2026-10-24 | C27: 2026 | D27: "DMK does what it promises and promises only what it can deliver": Tamil Nadu CM MK Stalin | E27: தொல்லியல் | F27: Archaeology / Excavation | G27: archaeological, keeladi | H27: Tamil Nadu | I27: aninews.in | J27: India | K27: English/Other | L27: https://aninews.in/news/national/general-news/dmk-does-what-it-promises-and-promises-only-what-it-can-deliver-tamil-nadu-cm-mk-stalin20260131191642/ | N27: Sivagangai (Tamil Nadu) [India], January 31 (ANI): Tamil Nadu Chief Minister MK Stalin on Saturday recalled Sivaganga's rich legacy of Tamil civilisation, valour and sacrifice, stating that the district symbolises resistance, freedom and social justice. Addressing a public function, he referred to t… | O27: full-text | P27: gdelt | Q27: 2026-10-24
A28: 27 | B28: 2026-10-24 | C28: 2026 | D28: "Election fear and fever have continued to haunt him": Kanimozhi slams EPS | E28: தொல்லியல் | F28: Archaeology / Excavation | G28: keeladi | H28: Tamil Nadu | I28: aninews.in | J28: India | K28: English/Other | L28: https://aninews.in/news/national/politics/election-fear-and-fever-have-continued-to-haunt-him-kanimozhi-slams-eps20260410081826/ | N28: Erode (Tamil Nadu) [India], April 10 (ANI): DMK leader Kanimozhi Karunanidhi on Thursday hit out at Leader of Opposition in Tamil Nadu assembly Edappadi Palaniswami and said "election fear and fever have continued to haunt him". Speaking in a campaign to support Tamil Nadu minister and DMK candidate… | O28: full-text | P28: gdelt | Q28: 2026-10-24
A29: 28 | B29: 2026-10-24 | C29: 2026 | D29: "How do corrupt individuals get whitewashed after joining BJP?" MK Stalin bombards centre with questions, raises various issues | E29: தொல்லியல் | F29: Archaeology / Excavation | G29: keeladi | H29: Tamil Nadu | I29: aninews.in | J29: India | K29: English/Other | L29: https://aninews.in/news/national/politics/how-do-corrupt-individuals-get-whitewashed-after-joining-bjp-mk-stalin-bombards-centre-with-questions-raises-various-issues20251018135601/ | N29: Chennai (Tamil Nadu) [India], October 18 (ANI): Tamil Nadu Chief Minister MK Stalin on Saturday lambasted the centre over the naming of crucial government projects and legislations in Hindi and Sanskrit, saying that people across the nation had multiple questions. Raising the issue of corrupt indivi… | O29: full-text | P29: gdelt | Q29: 2026-10-24
A30: 29 | B30: 2026-10-24 | C30: 2026 | D30: 2,600-year-old terracotta pipeline found in India | E30: தொல்லியல் | F30: Archaeology / Excavation | G30: archaeology, archaeological, archaeological excavations, keeladi | H30: Tamil Nadu | I30: sott.net | J30: Unknown | K30: English/Other | L30: https://www.sott.net/article/493855-2600-year-old-terracotta-pipeline-found-in-India | N30: OF THE TIMES During the 10th phase of archaeological excavations at the Keeladi archaeological site in Tamil Nadu, India, archaeologists uncovered a terracotta pipeline that shows the existence of an ancient water management practice practiced by humans 2,600 years ago. Ancient city Keeladi in south… | O30: full-text | P30: gdelt | Q30: 2026-10-24
A31: 30 | B31: 2026-10-24 | C31: 2026 | D31: Ancient ring well found at paddy field near Keeladi excavation site | E31: தொல்லியல் | F31: Archaeology / Excavation | G31: archaeological, archeology, archeological, excavation site, keeladi | H31: Tamil Nadu | I31: news.webindia123.com | J31: Unknown | K31: English/Other | L31: https://news.webindia123.com/news/Articles/India/20211220/3877488.html | N31: Saturday, October 24, 2026 News | | | Ancient ring well found at paddy field near Keeladi excavation site Chennai \| Monday, 2021 10:45:08 PM IST | | Workers digging a pit in a paddy field 100 metres away from the proposed museum at the Keeladi excavation site were in for a surprise when the top of … | O31: full-text | P31: gdelt | Q31: 2026-10-24
A32: 31 | B32: 2026-10-24 | C32: 2026 | D32: DMK MP Kanimozhi meets PM Modi, thanks him for upgrade of Thoothukudi airport | E32: தொல்லியல் | F32: Archaeology / Excavation | G32: keeladi, keezhadi | H32: Tamil Nadu | I32: news.webindia123.com | J32: Unknown | K32: English/Other | L32: https://news.webindia123.com/news/Articles/India/20250808/4347655.html | N32: Saturday, October 24, 2026 News | | | DMK MP Kanimozhi meets PM Modi, thanks him for upgrade of Thoothukudi airport New Delhi \| August 8, 2025 8:45:16 PM IST | | Dravida Munnetra Kazhagam (DMK) MP Kanimozhi on Friday met Prime Minister Narendra Modi in the national capital, where she raised importa… | O32: full-text | P32: gdelt | Q32: 2026-10-24
A33: 32 | B33: 2026-10-24 | C33: 2026 | D33: DMK does what it promises and promises only what it can deliver: Tamil Nadu CM MK Stalin | E33: தொல்லியல் | F33: Archaeology / Excavation | G33: archaeological, keeladi | H33: Tamil Nadu | I33: news.webindia123.com | J33: Unknown | K33: English/Other | L33: https://news.webindia123.com/news/Articles/India/20260131/4411075.html | N33: Saturday, October 24, 2026 News | | | "DMK does what it promises and promises only what it can deliver": Tamil Nadu CM MK Stalin Sivagangai (Tamil Nadu) \| January 31, 2026 7:50:19 PM IST | | Tamil Nadu Chief Minister MK Stalin on Saturday recalled Sivaganga's rich legacy of Tamil civilisation, valo… | O33: full-text | P33: gdelt | Q33: 2026-10-24
A34: 33 | B34: 2026-10-24 | C34: 2026 | D34: Dravidian iron for the Aryan horse - The Economic Times | E34: தொல்லியல் | F34: Archaeology / Excavation | G34: archaeology, keeladi | H34: Tamil Nadu, Egypt, China | I34: economictimes.indiatimes.com | J34: Unknown | K34: English/Other | L34: https://economictimes.indiatimes.com/opinion/et-commentary/dravidian-iron-for-the-aryan-horse/articleshow/123325961.cms | N34: Colonial historians argued the ‘Aryan invasion theory’ that light-skinned chariot-riding people destroyed Harappan cities, conquered India, enslaved local dark-skinned people and created the caste system. To counter this, there was the ‘out of India’ theory popularised by many Brahmins, that Harappa… | O34: full-text | P34: gdelt | Q34: 2026-10-24
A35: 34 | B35: 2026-10-24 | C35: 2026 | D35: Election fear and fever have continued to haunt him: Kanimozhi slams EPS | E35: தொல்லியல் | F35: Archaeology / Excavation | G35: keeladi | H35: Tamil Nadu | I35: news.webindia123.com | J35: Unknown | K35: English/Other | L35: https://news.webindia123.com/news/Articles/India/20260410/4437393.html | N35: Saturday, October 24, 2026 News | | | "Election fear and fever have continued to haunt him": Kanimozhi slams EPS Erode (Tamil Nadu) \| April 10, 2026 8:52:28 AM IST | | DMK leader Kanimozhi Karunanidhi on Thursday hit out at Leader of Opposition in Tamil Nadu assembly Edappadi Palaniswami and said "… | O35: full-text | P35: gdelt | Q35: 2026-10-24
A36: 35 | B36: 2026-10-24 | C36: 2026 | D36: Human skeletal remains unearthed at TN's Kondagai excavation site | E36: தொல்லியல் | F36: Archaeology / Excavation | G36: archaeology, archeology, excavation site, keeladi | H36: Tamil Nadu | I36: aninews.in | J36: India | K36: English/Other | L36: https://www.aninews.in/news/national/general-news/human-skeletal-remains-unearthed-at-tns-kondagai-excavation-site20200813140212/ | N36: Madurai (Tamil Nadu) [India], Aug 13 (ANI): Human skeletal remains were unearthed from the Kondagai excavation site near Tamil Nadu's Madurai by the State's Department of Archaeology, on Wednesday. The remains have been sent to Madurai Kamaraj University for DNA analysis. While speaking to ANI, Siva… | O36: full-text | P36: gdelt | Q36: 2026-10-24
A37: 36 | B37: 2026-10-24 | C37: 2026 | D37: Rs 8876.57 cr allocated to police department in Tamil Nadu's budget | E37: தொல்லியல் | F37: Archaeology / Excavation | G37: keeladi | H37: Tamil Nadu | I37: aninews.in | J37: India | K37: English/Other | L37: https://www.aninews.in/news/national/general-news/rs-887657-cr-allocated-to-police-department-in-tamil-nadus-budget20200214110902/ | N37: Chennai (Tamil Nadu) [India], Feb 14 (ANI): The Tamil Nadu government has allocated a total amount of Rs 8876.57 Crores for the police department in the budget for this financial year. "A total amount of Rs 8876.57 Crores has been allocated for the police department, including Rs 431 Crores for the … | O37: full-text | P37: gdelt | Q37: 2026-10-24
A38: 37 | B38: 2026-10-24 | C38: 2026 | D38: Skeletal remains of animal found at Manalur excavation site in Tamil Nadu | E38: தொல்லியல் | F38: Archaeology / Excavation | G38: archaeology, excavation site, keeladi, tnsda | H38: Tamil Nadu | I38: aninews.in | J38: India | K38: English/Other | L38: https://www.aninews.in/news/national/general-news/skeletal-remains-of-animal-found-at-manalur-excavation-site-in-tamil-nadu20200605102614/ | N38: Madurai (Tamil Nadu) [India], June 5 (ANI): Skeletal remains of an animal have been unearthed at Manalur near Madurai under the sixth phase of excavations at Keeladi site, undertaken by the Tamil Nadu State Department of Archaeology (TNSDA). Tamil Nadu Chief Minister Edappadi K Palaniswami had start… | O38: full-text | P38: gdelt | Q38: 2026-10-24
... A42: 41 | B42: 2026-10-24 | C42: 2026 | D42: Tamil Nadu: MK Stalin visits Sivaganga archaeology site | E42: தொல்லியல் | F42: Archaeology / Excavation | G42: archaeology, archeology, keeladi | H42: Tamil Nadu | I42: aninews.in | J42: India | K42: English/Other | L42: https://aninews.in/news/national/general-news/tamil-nadu-mk-stalin-visits-sivaganga-archaeology-site20190927172127/ | N42: Sivaganga (Tamil Nadu) [India], Sept 27 (ANI): Opposition leader and Dravida Munnetra Kazhagam (DMK) president MK Stalin on Friday visited the Keeladi archaeology site as part of the fifth phase of excavation in Sivaganga in Tamil Nadu. The fifth phase of excavation started in June and likely to clo… | O42: full-text | P42: gdelt | Q42: 2026-10-24
A43: 42 | B43: 2026-10-23 | C43: 2026 | D43: Rare Simhavishnu-era hero stone sheds light on Pallava society, Tamil writing | E43: நடுகல் | F43: Hero stone / Memorial stone | G43: hero stone, hero-stone | I43: magzter.com | J43: Unknown | K43: English/Other | L43: https://www.magzter.com/stories/newspaper/The-New-Indian-Express-Chennai/RARE-SIMHAVISHNUERA-HERO-STONE-SHEDS-LIGHT-ON-PALLAVA-SOCIETY-TAMIL-WRITING | O43: title-only | P43: gnews | Q43: 2026-10-24
...

Sheet Research papers
A1: No | B1: Year | C1: Date | D1: Title | E1: Authors | F1: Journal / venue | G1: Keyword group (Tamil) | H1: Keyword group (English) | I1: Matched terms | J1: Places mentioned | K1: Language | L1: Link | M1: Free full text | N1: DOI | O1: Abstract (start) | P1: Found via | Q1: Found on
A2: 1 | B2: 2026 | C2: 2026-05-25 | D2: "Regional Traditions of Smoking: A Comparative Study of Terracotta Pipes in South and North India with Evidence from Vembakottai" | E2: P. Baskar | F2: Zenodo (CERN European Organization for Nuclear Research) | G2: தொல்லியல் | H2: Archaeology / Excavation | I2: archaeology, keeladi, adichanallur, vembakottai | J2: Tamil Nadu | K2: English/Other | L2: https://doi.org/10.5281/zenodo.20376141 | M2: https://doi.org/10.5281/zenodo.20376141 | N2: 10.5281/zenodo.20376141 | O2: Abstract: Terracotta smoking pipes constitute an important yet understudied class of early modern artifacts in South Asian archaeology, reflecting the widespread adoption of tobacco following its introduction in the late 16th century CE. This study presents a detailed analysis of a group of terracotta pipe bowls recovered from Vembakottai, Tamil Nadu, focusing on their morphology, manufacturing technology, use-wear patterns, and chronological significance. The assemblage is characterized by predominantly globular and bulbous forms with short stem sockets, minimal decoration, and clear evidence | P2: OpenAlex | Q2: 2026-10-17
A3: 2 | B3: 2026 | C3: 2026-03-11 | D3: A CULTURAL AND HISTORICAL STUDY OF HERO-STONE (NADUKAL) WORSHIP AMONG MALAYALIS (TRIBLE) IN THE KALVARAYAN HILLY AREA OF HERO-STONE WORSHIP | E3: Asaikkannu Sakthivel; Franklin Thambi Jose. S | F3: International Journal of Education Psychology and Counseling | G3: நடுகல், தொல்லியல் | H3: Hero stone / Memorial stone, Archaeology / Excavation | I3: hero stone, hero stones, hero-stone, nadukal, archaeology, archaeological, megalithic | J3: Tamil Nadu | K3: English/Other | L3: https://doi.org/10.35631/ijepc.1162036 | M3: https://doi.org/10.35631/ijepc.1162036 | N3: 10.35631/ijepc.1162036 | O3: Background: This paper analyzes the hero-stone (Nadukal) traditions of the Malayali tribes in the Kalrayan Hills. From the Megalithic era through the Sangam age, erecting memorials for warriors who perished in battle was a cornerstone of Tamil culture, extensively documented in the Tolkappiyam, Sangam literature, and devotional hymns. The study employs a Qualitative Descriptive-Historical Design. It adopts a longitudinal perspective to track the evolution of worship from prehistoric archaeological evidence to contemporary ethnographic practices. By integrating archaeology and anthropology, the | P3: OpenAlex | Q3: 2026-10-17
A4: 3 | B4: 2026 | C4: 2026-06-05 | D4: A Comprehensive Review on the Origin and Evolution of Varmam | E4: L.Deepa Nandhini | F4: Journal of chemical health risks | G4: கல்வெட்டு, தொல்லியல் | H4: Inscription / Epigraphy, Archaeology / Excavation | I4: inscriptions, archaeological | K4: English/Other | L4: https://jchr.org/index.php/JCHR/article/view/14545 | M4: https://jchr.org/index.php/JCHR/article/download/14545/7814 | O4: Introduction: Varmam is a unique therapeutic and martial science of the Siddha Medicine that focuses on vital energy points of the human body for the prevention and management of diseases Objectives: The present review aims to explore the historical origin, evolution, and therapeutic significance of Varmam through classical literature and contemporary evidence. Methods: A narrative literature review was conducted using classical Siddha texts, Tamil literary sources, palm-leaf manuscripts, archaeological evidences, and published scientific articles retrieved from databases including PubMed, Sco | P4: OpenAlex | Q4: 2026-10-17
A5: 4 | B5: 2026 | C5: 2026-01-26 | D5: A Computational Framework for the Structural Analysis of the Indus Valley Script: Integrating Comprehensive Inference, Nexus Validation, and Cross-Script Motif Alignment | E5: August Tudor | F5: Zenodo (CERN European Organization for Nuclear Research) | G5: கல்வெட்டு, தொல்லியல் | H5: Inscription / Epigraphy, Archaeology / Excavation | I5: inscriptions, graffiti marks, archaeological | J5: Tamil Nadu | K5: English/Other | L5: https://doi.org/10.5281/zenodo.18371284 | M5: https://doi.org/10.5281/zenodo.18371284 | N5: 10.5281/zenodo.18371284 | O5: The Indus Valley Script (IVS), dating to c. 2600–1900 BCE, remains one of the world's most enduring undeciphered writing systems. Despite over a century of scholarship, the absence of bilingual texts and the brevity of inscriptions (median 4–5 signs) have prevented consensus on whether the script encodes a full language or functions as a restricted symbolic system. This paper presents CI+NIS, an original, reproducible computational framework that integrates Comprehensive Inference (CI)—a dynamic Bayesian-Frequentist fusion—with the Nexus Inferential System (NIS), which validates inferred struc | P5: OpenAlex | Q5: 2026-10-17
A6: 5 | B6: 2026 | C6: 2026-09-01 | D6: A Critical Study of the Social Status of the Brahmins Belonging to Various Vedic Śākhās Mentioned in Ancient Indian Inscriptions | E6: Deepshikha Mondal; Dr. Nandadulal Mandal | F6: Zenodo (CERN European Organization for Nuclear Research) | G6: கல்வெட்டு | H6: Inscription / Epigraphy | I6: inscriptions, copper plates | K6: English/Other | L6: https://doi.org/10.5281/zenodo.22709831 | M6: https://doi.org/10.5281/zenodo.22709831 | N6: 10.5281/zenodo.22709831 | O6: Abstract: Inscriptions constitute the earliest and most fundamental primary source for the study of ancient Indian history and literature. These epigraphic records illuminate multifaceted dimensions of the socio-political, cultural, and religious history of contemporary India, as well as the preservation of the Indian knowledge tradition. In particular, land-grant inscriptions—recorded on copper plates and stone slabs—provide detailed documentation regarding the gotra (lineage), pravara (ancestral heritage), śākhā (Vedic recension/branch), domicile, and scholarly devotion of the Brahmins of th | P6: OpenAlex | Q6: 2026-10-17
A7: 6 | B7: 2026 | C7: 2026-09-21 | D7: A Historical Study of the Tamil Inscriptions Discovered at the Buddhist Heritage Site of Velgam Vehera | E7: U.S.Y. Sahan Mahesh Senarath yapa | F7: Zenodo (CERN European Organization for Nuclear Research) | G7: கல்வெட்டு, தொல்லியல் | H7: Inscription / Epigraphy, Archaeology / Excavation | I7: inscriptions, archaeology | J7: Sri Lanka | K7: English/Other | L7: https://doi.org/10.5281/zenodo.22870959 | M7: https://doi.org/10.5281/zenodo.22870959 | N7: 10.5281/zenodo.22870959 | O7: The ruins of an ancient Buddhist monastery are found at Periyakulam in the Kattukulampattu division of the Trincomalee District. Formerly referred to as Natanar Kovil, it is known today as Velgam Vehera. The ruins of this monastery exhibit distinct Tamil architectural characteristics. Notably, at least sixteen Tamil inscriptions dating to the eleventh century, during the reigns of several Chola emperors, have been discovered here. Fourteen of these have been published by Professors K. Indrapala and A. Velupillai. Broadly, these epigraphs indicate that this Buddhist institution in Periyakulam f | P7: OpenAlex | Q7: 2026-10-16
A8: 7 | B8: 2026 | C8: 2026-04-20 | D8: A Structural-Semantic Model of the Indus Script: Syntagmatic Patterns and Dravidian Continuity | E8: Ella Kiseleva | F8: Zenodo (CERN European Organization for Nuclear Research) | G8: கல்வெட்டு, தொல்லியல் | H8: Inscription / Epigraphy, Archaeology / Excavation | I8: inscription, archaeological | J8: Tamil Nadu | K8: English/Other | L8: https://doi.org/10.5281/zenodo.19662775 | M8: https://doi.org/10.5281/zenodo.19662775 | N8: 10.5281/zenodo.19662775 | O8: This study presents a structural-semantic model of the Indus Valley script based on the statistical analysis of sign sequences in the EBUDS corpus (Yadav et al., TIFR, 2007). The model proposes that Indus signs function as operators within fixed syntagmatic patterns rather than as phonetic notations. The interpretation is validated through internal positional analysis and external comparison with Tamil Siddha concepts and Vedic Sanskrit. The core of the model consists of eight high-frequency sign sequences extracted from the EBUDS corpus. These sequences form a coherent syntagmatic structure t | P8: OpenAlex | Q8: 2026-10-17
A9: 8 | B9: 2026 | C9: 2026-05-03 | D9: A Study of Maritime Trade in the Tamil Twin Epics | E9: A, Prasanth | F9: International Research Journal of Tamil | G9: தொல்லியல் | H9: Archaeology / Excavation | I9: archaeological | K9: English/Other | L9: https://irjt.iorpress.org/index.php/irjt/article/view/2582 | O9: Numerous studies conducted by governmental and non-governmental researchers have sought to establish the antiquity and richness of Tamil civilization. Drawing upon archaeological evidence and literary sources, these studies have contributed significantly to understanding the historical identity and achievements of the Tamil people. Among the many aspects of Tamil civilization, maritime trade occupies a prominent place, demonstrating the Tamils' active participation in overseas commerce from ancient times. In this context, the present study explores the maritime trade practices reflected in the | P9: Journal: International Research Journal of Tamil | Q9: 2026-10-16
A10: 9 | B10: 2026 | C10: 2026-05-03 | D10: A Study of Tamil Culture through Akananuru | E10: S, Mary Janet; S, Mejila Jeevi | F10: International Research Journal of Tamil | G10: நடுகல் | H10: Hero stone / Memorial stone | I10: hero stones, nadukal | K10: English/Other | L10: https://irjt.iorpress.org/index.php/irjt/article/view/2588 | O10: Akananuru occupies a distinguished place in the Sangam literary tradition as a classical anthology that vividly portrays the inner world of human emotions and love with remarkable literary sophistication. It integrates human feelings, the various stages of love, natural landscapes, and social ethics into a unified poetic expression. Consequently, Akananuru is valued not only as a literary masterpiece but also as an important cultural document that preserves the traditions and way of life of the ancient Tamils.An examination of Tamil culture through Akananuru reveals that culture is not merely | P10: Journal: International Research Journal of Tamil | Q10: 2026-10-16
A11: 10 | B11: 2026 | C11: 2026-02-12 | D11: A Sustainable Tourism Model for Keeladi and the Sangam Landscape | E11: Arachchi Mudiyanselage Kanishka Kalhari; G. Paranthaman | F11: Shanlax International Journal of Management | G11: தொல்லியல் | H11: Archaeology / Excavation | I11: archaeological, excavation site, keeladi | J11: Sri Lanka | K11: English/Other | L11: https://doi.org/10.34293/management.v13is1-i2-feb.10400 | M11: https://shanlaxjournals.in/journals/index.php/management/article/download/10400/9055 | N11: 10.34293/management.v13is1-i2-feb.10400 | O11: This research addresses the critical need for a sustainable tourism paradigm in the Vaigai River Valley which is anchored on the record-breaking excavation site of Keeladi. Although Keeladi with its 6 th century BCE urban sophistication, demonstrated through carbon dating (580 BCE) reinvents the history of South Asia, the contemporary tourism cannot be seen as changing or tied to the local economy. In this paper, there are several suggestions to convert the corridor, which is a passive viewing model, to an active narrative immersion circuit through offerings of an Integrated Heritage Landscape | P11: OpenAlex | Q11: 2026-10-17
A12: 11 | B12: 2026 | C12: 2026-03-04 | D12: AI Powered OCR Solution for Tamil Historical Document | E12: Ms.T. Saraswathi; HARISH S; Abishek Kumar B | F12: International Conference on Intelligent Sustainable Systems (ICISS) | G12: கல்வெட்டு | H12: Inscription / Epigraphy | I12: inscriptions | K12: English/Other | L12: https://doi.org/10.1109/iciss67859.2026.11453612 | N12: 10.1109/iciss67859.2026.11453612 | O12: Palm leaves, plates of copper and stone inscriptions which were used in ancient Tamil are an invaluable cultural source yet manual reading of these sources is largely hampered by the physical decay, the blurring of the scripts and complicated ligatures. Existing optical character recognition (OCR) technologies cannot recognize such historical documents well due to noise, variation in spacing and changes in style. This project presents an artificial intelligence-based OCR system that is specifically trained to work with ancient Tamil manuscripts. Through a semi-supervised form of deep learning, | P12: OpenAlex | Q12: 2026-10-17
A13: 12 | B13: 2026 | C13: 2026-07-10 | D13: AI – Based Recognition and Interpretation of Ancient Tamil Inscriptions and Palm Leaf Manuscripts | E13: T. Ramanandhini, Dr. M. Gopianand, Gowtham K, M. Safeeka Department of Computer Applications PSNA College of Engineering and Technology, Dindigul,India | F13: Zenodo (CERN European Organization for Nuclear Research) | G13: கல்வெட்டு | H13: Inscription / Epigraphy | I13: inscriptions | K13: English/Other | L13: https://doi.org/10.5281/zenodo.23036680 | M13: https://doi.org/10.5281/zenodo.23036680 | N13: 10.5281/zenodo.23036680 | O13: Ancient Tamil manuscripts and carvescontain valuable historical, literary, and culturalinformation. Therefore, many items have deterioratedover time, making their explanation difficult. Thisstudy presents a web-based system designed torecognize and interpret ancient Tamil scripts usingthe Gemini Vision model. The proposed system viewsthe images of manuscripts and carves the text content,which is changed into simple Tamil explanations forbetter understanding. This enables modern readersto access and interpret ancient knowledge moreeasily than before. Flask and MySQL were used tomanage user auth | P13: OpenAlex | Q13: 2026-10-16
A14: 13 | B14: 2026 | C14: 2026-09-04 | D14: ARCHAEOLOGICAL AND HISTORICAL EVIDENCE FOR FOREST RIGHTS CLAIMS OF NARIYUTHU VILLAGE UNDER THE FOREST RIGHTS ACT, 2006 | E14: THANUSHKODI S | F14: Zenodo (CERN European Organization for Nuclear Research) | G14: தொல்லியல் | H14: Archaeology / Excavation | I14: archaeological | J14: Tamil Nadu | K14: English/Other | L14: https://doi.org/10.5281/zenodo.22307110 | M14: https://doi.org/10.5281/zenodo.22307110 | N14: 10.5281/zenodo.22307110 | O14: PURPOSE AND METHODOLOGY: A comprehensive compilation of epigraphical and archaeological evidence sourced from the Avanam journal (Tamil Nadu Archaeological Society), academic research, archival district gazetteers, and direct field data. This evidence dossier has been systematically compiled under the Forest Rights Act, 2006, and the Amended Rules, 2012 (Rule 13), to legally substantiate the traditional land rights of the people of Nariyuthu. | P14: OpenAlex | Q14: 2026-10-17
A15: 14 | B15: 2026 | C15: 2026-06-18 | D15: Accounting approaches to the study of historical Tamil events | E15: Thangavelu Chinnasamy | F15: De Computis - Revista Española de Historia de la Contabilidad | G15: கல்வெட்டு, தொல்லியல் | H15: Inscription / Epigraphy, Archaeology / Excavation | I15: inscriptions, archaeological, keeladi, adichanallur | K15: English/Other | L15: https://doi.org/10.26784/issn.1886-1881.23.1.13660 | M15: https://www.upo.es/revistas/index.php/decomputis/article/download/13660/11422 | N15: 10.26784/issn.1886-1881.23.1.13660 | O15: This study examines the historical development of accounting in Tamil civilization based on archaeological, literary, epigraphic, and administrative evidence, tracing its evolution from the Sangam period (300 BCE–300 CE) to the institutional systems of the Chola and Pandya dynasties (9th–14th centuries CE). Findings from sites such as Keeladi, Adichanallur, and Poompuhar reveal early urban and commercial organization that required structured economic record-keeping. Tamil literary sources, including the Thirukkural and Sangam anthologies, along with temple inscriptions and palm-leaf manuscript | P15: OpenAlex | Q15: 2026-10-17
A16: 15 | B16: 2026 | C16: 2026-04-19 | D16: Addendum to Molina (2026e) — The Meluhhan Commercial Package and the Keezhadi Phonologization Event: Triple-Point Verification of Proto-Dravidian Continuity from the Indus Valley to Tamil-Brahmi (2500-600 BCE) | E16: Juan Gabriel Molina | F16: Zenodo (CERN European Organization for Nuclear Research) | G16: கல்வெட்டு, தொல்லியல் | H16: Inscription / Epigraphy, Archaeology / Excavation | I16: tamil-brahmi, tamil brahmi, archaeology, archaeological, megalithic, keeladi, keezhadi, tnsda | J16: Tamil Nadu | K16: English/Other | L16: https://doi.org/10.5281/zenodo.19655074 | M16: https://doi.org/10.5281/zenodo.19655074 | N16: 10.5281/zenodo.19655074 | O16: This deposit is a formal addendum to Molina (2026e), FMX-IVT-2026-PUB, which established the Meluhhan Interregnum Hypothesis and the selective survival of Indus administrative frame signs into the South Indian Megalithic period (Fisher p = 1.62 x 10^-19, odds ratio 16.7, medial control 0/12). The present addendum extends that deposit with four additional findings. First, triple-point verification of Proto-Dravidian as the spoken language of the Harappan/Meluhhan civilization. The phonetic anchor is the sesame loanword ellu (DEDR 834), frozen in Akkadian and Sumerian at the Harappan institution | P16: OpenAlex | Q16: 2026-10-16
A17: 16 | B17: 2026 | C17: 2026-04-19 | D17: Addendum to Molina (2026e) — The Meluhhan Commercial Package and the Keezhadi Phonologization Event: Triple-Point Verification of Proto-Dravidian Continuity from the Indus Valley to Tamil-Brahmi (2500-600 BCE) — Private Technical Record | E17: Juan Gabriel Molina | F17: Zenodo (CERN European Organization for Nuclear Research) | G17: கல்வெட்டு, தொல்லியல் | H17: Inscription / Epigraphy, Archaeology / Excavation | I17: tamil-brahmi, tamil brahmi, keezhadi | K17: English/Other | L17: https://doi.org/10.5281/zenodo.19655145 | M17: https://doi.org/10.5281/zenodo.19655145 | N17: 10.5281/zenodo.19655145 | O17: Private technical companion to public deposit FMX-IVT-2026-ADD-PUB and addendum private record to main deposit FMX-IVT-2026-PVT. Deposited as a restricted record for priority timestamping only. Not available for public access. Full analytical methodology and proprietary technical record withheld pending peer-reviewed publication. SHA-256 of this document is embedded in public deposit FMX-IVT-2026-ADD-PUB. Part of the Molina Methodology cross-corpus structural analysis series. Reference: FMX-IP-2026. | P17: OpenAlex | Q17: 2026-10-16
A18: 17 | B18: 2026 | C18: 2026-06-01 | D18: Administrative Procedures in the Chola Anaimangalam (Leiden) Plates: Reconstructing the Bureaucratic Workflow of a Land Grant | E18: Hemanth Thiru | F18: Zenodo (CERN European Organization for Nuclear Research) | G18: கல்வெட்டு | H18: Inscription / Epigraphy | I18: inscription, copper plate, copper plates, copper-plate | K18: English/Other | L18: https://doi.org/10.5281/zenodo.20493947 | M18: https://doi.org/10.5281/zenodo.20493947 | N18: 10.5281/zenodo.20493947 | O18: The Anaimangalam Copper Plates, widely known as the Leiden Copper Plates and formerly preserved at Leiden University1, constitute an important epigraphical record from the Chola period. The inscription documents a land grant issued during the reign of Rajaraja Chola I in support of the Chulamani Vihara at Nagapattinam, a Buddhist institution associated with the rulers of the Srivijaya kingdom. While the plates are often discussed in relation to Chola lineage, and maritime diplomacy, they also preserve exceptionally detailed evidence concerning administrative procedure and bureaucratic governan | P18: OpenAlex | Q18: 2026-10-17
A19: 18 | B19: 2026 | C19: 2026-01-07 | D19: Advanced Deep Learning OCR Algorithm for Deciphering and Digitizing Chola Period Tamil Inscriptions | E19: M Rajalakshmi; Shanthi Jeyabal; Manoj Ranjan Mishra; Bibhuti Bhusan Dash; Utpal Chandra De; Sudhansu Shekhar Patra | F19: International Conference on Mobile Computing and Sustainable Informatics (ICMCSI) | G19: கல்வெட்டு | H19: Inscription / Epigraphy | I19: inscriptions | K19: English/Other | L19: https://doi.org/10.1109/icmcsi67283.2026.11412629 | N19: 10.1109/icmcsi67283.2026.11412629 | O19: The Tamil inscriptions of the Chola are important in terms of conserving historical, cultural and linguistic history of the area. It could be tedious and time-consuming to read these inscriptions with the hand though. This paper discusses a customized Optical Character Recognition (OCR) system that facilitates easier digitization and transcription of old Tamil inscriptions. The solution is considered to be a combination of the YOLOv8, Tensorflow, and PyTorch systems that will promote the effectiveness of character recognition, segmentation, and detection. Our experiment with the method on a nu | P19: OpenAlex | Q19: 2026-10-16
A20: 19 | B20: 2026 | C20: 2026-04-17 | D20: An Automated Tamil Inscription Translator using Deep Learning for Robust Character Recognition and Epigraphic Text Formation | E20: Dr. P. Manivanan, R. Premrajesh, P. Senthamil Selvi and K. Murugananthi | F20: Zenodo (CERN European Organization for Nuclear Research) | G20: கல்வெட்டு | H20: Inscription / Epigraphy | I20: inscription, inscriptions | K20: English/Other | L20: https://doi.org/10.5281/zenodo.19634764 | M20: https://doi.org/10.5281/zenodo.19634764 | N20: 10.5281/zenodo.19634764 | O20: ABSTRACT An automated system developed using Deep Learning techniques was proposed to translate ancient Tamil inscriptions, characterized by their difficulty in recognizing characters, forming epigraphic text, degraded conditions, background noise, and irregular shaped characters, through the use of a combination of image enhancement techniques, Optical Character Recognition (OCR), and Natural Language Processing (NLP) to enhance the accuracy of recognition and create a coherent Tamil document. The OCR utilized a convolutional neural network (CNN) for character recognition while an artificial | P20: OpenAlex | Q20: 2026-10-16
A21: 20 | B21: 2026 | C21: 2026-07-20 | D21: An Epigraphical Corpus of 10 Indus Valley Tablets: Mirror Inversions, Traced Overlays, Dravidian Etymological Dictionary (DEDR) Tamil-Brahmi Glosses and English conceptual meaning | E21: Prabhakaran Karunakaran | F21: Zenodo (CERN European Organization for Nuclear Research) | G21: கல்வெட்டு | H21: Inscription / Epigraphy | I21: tamil-brahmi, tamil brahmi | K21: English/Other | L21: https://doi.org/10.5281/zenodo.21452528 | M21: https://doi.org/10.5281/zenodo.21452528 | N21: 10.5281/zenodo.21452528 | O21: NOTICE: Public access to the files in this repository has been temporarily restricted by the author | P21: OpenAlex | Q21: 2026-10-16
A22: 21 | B22: 2026 | C22: 2026-08-20 | D22: Ancient Tamil Governance Analytics: Mining the Uthiramerur Inscriptions for Democratic Insights | E22: Ramanathan Srinivasan; P. S. Aithal | F22: Zenodo (CERN European Organization for Nuclear Research) | G22: கல்வெட்டு | H22: Inscription / Epigraphy | I22: inscriptions | J22: Tamil Nadu | K22: English/Other | L22: https://doi.org/10.5281/zenodo.22031949 | M22: https://doi.org/10.5281/zenodo.22031949 | N22: 10.5281/zenodo.22031949 | O22: Purpose: Using data analytics and digital humanities, this paper investigates the governance records of Uthiramerur, a tenth-century Tamil village. The Uthiramerur assembly (sabha) is notable for its use of the kuṭavōlai, a palm-leaf ballot, for drawing lots. The records primarily exist as stone inscriptions placed during the reign of Parāntaka Chola I (c. 919 – 921 CE). The palm-leaf ballots, by contrast, were ephemeral. The inscriptions of Uthiramerur were treated as data, and the construction of the electoral algorithm and design of the committees (variyams) along with the rules of disquali | P22: OpenAlex | Q22: 2026-10-16
A23: 22 | B23: 2026 | C23: 2026-08-20 | D23: Ancient Tamil Governance Analytics: Mining the Uthiramerur Inscriptions for Democratic Insights | E23: Ramanathan Srinivasan; P. S. Aithal | F23: Poornaprajna International Journal of Philosophy & Languages (PIJPL) | G23: கல்வெட்டு | H23: Inscription / Epigraphy | I23: inscriptions | J23: Tamil Nadu | K23: English/Other | L23: https://doi.org/10.64818/pijpl.3107.4634.0053 | M23: https://www.poornaprajnapublication.com/index.php/pijpl/article/download/241/232/462 | N23: 10.64818/pijpl.3107.4634.0053 | O23: Purpose: Using data analytics and digital humanities, this paper investigates the governance records of Uthiramerur, a tenth-century Tamil village. The Uthiramerur assembly (sabha) is notable for its use of the kuṭavōlai, a palm-leaf ballot, for drawing lots. The records primarily exist as stone inscriptions placed during the reign of Parāntaka Chola I (c. 919 – 921 CE). The palm-leaf ballots, by contrast, were ephemeral. The inscriptions of Uthiramerur were treated as data, and the construction of the electoral algorithm and design of the committees (variyams) along with the rules of disquali | P23: OpenAlex | Q23: 2026-10-16
A24: 23 | B24: 2026 | C24: 2026-01-12 | D24: Archaeological Excavation Sites in Theni District: A Study on Iron Age and Early Historic Antiquities in Theni District | E24: Dr. S. Kasthuri | F24: Zenodo (CERN European Organization for Nuclear Research) | G24: தொல்லியல் | H24: Archaeology / Excavation | I24: archaeological, archaeological excavation | J24: Tamil Nadu | K24: English/Other | L24: https://doi.org/10.5281/zenodo.18222328 | M24: https://doi.org/10.5281/zenodo.18222328 | N24: 10.5281/zenodo.18222328 | O24: The Theni district of Tamil Nadu occupies a significant position in understanding the cultural developments of South India during the Iron Age and Early Historic periods. Archaeological evidence from this region, particularly burial monuments and habitation remains, indicates sustained human occupation from prehistoric times onward. Although earlier discoveries were reported during the colonial period and later surveys by scholars of the Archaeological Survey of India and Tamil University, focused and systematic investigation of Theni district remained limited. The present study addresses this | P24: OpenAlex | Q24: 2026-10-17
A25: 24 | B25: 2026 | C25: 2026-01-08 | D25: Archaeological Heritage of Tamil Nadu: Mahabalipuram | E25: Dr. A. Jesintha Vilveena | F25: Zenodo (CERN European Organization for Nuclear Research) | G25: தொல்லியல் | H25: Archaeology / Excavation | I25: archaeology, archaeological | J25: Tamil Nadu | K25: English/Other | L25: https://doi.org/10.5281/zenodo.18185250 | M25: https://doi.org/10.5281/zenodo.18185250 | N25: 10.5281/zenodo.18185250 | O25: Abstract Historians have two major avenues which they take to better understand the ancient world: archaeology and the study of source texts. Primary sources are those sources closest to the origin of the information or idea under study. Primary sources have been distinguished from secondary sources, which often cite, comment on, or build upon primary sources. Archaeological sites are merely the residues of settlements and structures, reduced to rubble and earthworks by decay, erosion, stone-robbing and the invasions of plant and animal life. Mahabalipuram is a monument complex on the Coromend | P25: OpenAlex | Q25: 2026-10-17
A26: 25 | B26: 2026 | C26: 2026-07-16 | D26: Architectural Historiography of the Airavatesvara Temple: Revisiting Chola Heritage through Epigraphic and Cultural Narratives | E26: K. Selva Kumar; S. Thangaraju | F26: International Journal of Arts Architecture & Design | G26: கல்வெட்டு, தொல்லியல் | H26: Inscription / Epigraphy, Archaeology / Excavation | I26: inscriptions, archaeological | K26: English/Other | L26: https://doi.org/10.62030/2026julypaper3 | M26: https://worlduniversityofdesign.ac.in/JAARD/wp-content/uploads/2026/07/3.-NEW-JAARD_-selva-kumar.docx.pdf | N26: 10.62030/2026julypaper3 | O26: The Airavatesvara Temple at Darasuram is widely regarded as one of the most refined creations of Later Chola architecture and sacred artistic imagination. Constructed during the reign of Rajaraja II in the twelfth century CE, the monument reflects the maturity of Chola artistic traditions and religious patronage. This article revisits the historiography of Chola temple heritage by closely examining the epigraphic, architectural, and cultural materials associated with Darasuram. Drawing extensively from the works of C. Sivaramamurti, S.R. Balasubrahmanyam, S.R. Krishnamurthi, and G.J.R. Mevisse | P26: OpenAlex | Q26: 2026-10-17
A27: 26 | B27: 2026 | C27: 2026-09-15 | D27: Beekeeping-Mediated Yield Enhancement and Monofloral Honey Production in Moringa (Moringa oleifera) Orchards | E27: Stephen Devanesan; Abraham Verghese; K. S. Premila; M. A. Rashmi | F27: Insect Environment | G27: தொல்லியல் | H27: Archaeology / Excavation | I27: korkai | J27: Tamil Nadu | K27: English/Other | L27: https://doi.org/10.55278/glii2516 | N27: 10.55278/glii2516 | O27: The drumstick tree (Moringa oleifera Lam.) is a nutrient-rich, entomophilous tree crop whose flowers depend heavily on insect visitation for fruit set, yet its association with managed honey bees has received little documented attention. This study reports on-farm observations from a moringa-growing belt in Korkai Manaloor, Eral, Tuticorin (Tamil Nadu), where migratory colonies of Apis cerana indica were introduced into orchards at approximately 5% flowering. Bee-assisted pollination increased fruit set by up to 30-fold on tagged branches, alongside marked gains in fruit size and weight, with | P27: OpenAlex | Q27: 2026-10-17
